<?xml version="1.0" encoding="utf-8"?>
<!-- This URDF was automatically created by SolidWorks to URDF Exporter! Originally created by Stephen Brawner (brawner@gmail.com) 
     Commit Version: 1.6.0-4-g7f85cfe  Build Version: 1.6.7995.38578
     For more information, please see http://wiki.ros.org/sw_urdf_exporter -->
<robot name="ask_3" xmlns:xacro="http://www.ros.org/wiki/xacro">
  <xacro:include filename="$(find ask_3_description)/urdf/ask_3.gazebo" />
  
  <!-- Used for fixing robot to Gazebo -->
  <link name="world"/>

  <joint name="fixed" type="fixed">
    <parent link="world"/>
    <child link="base"/>
    <origin rpy="0 0 0" xyz="0 0 0.65"/>
    <!--origin rpy="0 0 0" xyz="0 0 0.498093197403"/-->
  </joint>
  
  <link
    name="base">
    <inertial>
      <origin
        xyz="0.014593 0.00028184 -0.00016073"
        rpy="0 0 0" />
      <mass
        value="9.6967" />
      <inertia
        ixx="0.027851"
        ixy="0.00062733"
        ixz="-7.4684E-05"
        iyy="0.0296"
        iyz="-0.00011078"
        izz="0.048661" />
    </inertial>
    <visual>
      <origin
        xyz="0 0 0"
        rpy="0 0 0" />
      <geometry>
        <mesh
          filename="package://ask_3_description/meshes/base.STL" />
      </geometry>
      <material
        name="">
        <color
          rgba="0.75294 0.75294 0.75294 1" />
      </material>
    </visual>
    <collision>
      <origin
        xyz="0 0 0"
        rpy="0 0 0" />
      <geometry>
        <mesh
          filename="package://ask_3_description/meshes/base.STL" />
      </geometry>
    </collision>
  </link>
  <link
    name="LF_Link1">
    <inertial>
      <origin
        xyz="0.015742 2.0008E-06 0.05652"
        rpy="0 0 0" />
      <mass
        value="0.84408" />
      <inertia
        ixx="0.0011915"
        ixy="-2.9889E-08"
        ixz="1.8508E-06"
        iyy="0.00074578"
        iyz="5.548E-08"
        izz="0.00064082" />
    </inertial>
    <visual>
      <origin
        xyz="0 0 0"
        rpy="0 0 0" />
      <geometry>
        <mesh
          filename="package://ask_3_description/meshes/LF_Link1.STL" />
      </geometry>
      <material
        name="">
        <color
          rgba="0.89804 0.91765 0.92941 1" />
      </material>
    </visual>
    <collision>
      <origin
        xyz="0 0 0"
        rpy="0 0 0" />
      <geometry>
        <mesh
          filename="package://ask_3_description/meshes/LF_Link1.STL" />
      </geometry>
    </collision>
  </link>
  <joint
    name="LF_HAA"
    type="revolute">
    <origin
      xyz="0.1965 0.072 0"
      rpy="-1.5708 0 -1.5708" />
    <parent
      link="base" />
    <child
      link="LF_Link1" />
    <axis
      xyz="0 0 1" />
    <limit
      lower="-3.14"
      upper="3.14"
      effort="50"
      velocity="1000" />
  </joint>
  <link
    name="LF_Link2">
    <inertial>
      <origin
        xyz="-0.016452 0.016693 0.067293"
        rpy="0 0 0" />
      <mass
        value="1.8166" />
      <inertia
        ixx="0.003278"
        ixy="0.001787"
        ixz="-2.1595E-06"
        iyy="0.0035781"
        iyz="1.8742E-06"
        izz="0.0065662" />
    </inertial>
    <visual>
      <origin
        xyz="0 0 0"
        rpy="0 0 0" />
      <geometry>
        <mesh
          filename="package://ask_3_description/meshes/LF_Link2.STL" />
      </geometry>
      <material
        name="">
        <color
          rgba="0.027451 0.40784 0.36471 1" />
      </material>
    </visual>
    <collision>
      <origin
        xyz="0 0 0"
        rpy="0 0 0" />
      <geometry>
        <mesh
          filename="package://ask_3_description/meshes/LF_Link2.STL" />
      </geometry>
    </collision>
  </link>
  <joint
    name="LF_HFE"
    type="revolute">
    <origin
      xyz="0.004 0 0.066"
      rpy="0.0 -1.5708 0" />
    <parent
      link="LF_Link1" />
    <child
      link="LF_Link2" />
    <axis
      xyz="0 0 1" />
    <limit
      lower="-3.14"
      upper="3.14"
      effort="50"
      velocity="1000" />
  </joint>
  <link
    name="LF_Link3">
    <inertial>
      <origin
        xyz="0.070778 0.071405 -0.0025021"
        rpy="0 0 0" />
      <mass
        value="0.20609" />
      <inertia
        ixx="0.00069042"
        ixy="-0.00080696"
        ixz="1.2982E-08"
        iyy="0.001043"
        iyz="8.2699E-09"
        izz="0.0017245" />
    </inertial>
    <visual>
      <origin
        xyz="0 0 0"
        rpy="0 0 0" />
      <geometry>
        <mesh
          filename="package://ask_3_description/meshes/LF_Link3.STL" />
      </geometry>
      <material
        name="">
        <color
          rgba="0.89804 0.91765 0.92941 1" />
      </material>
    </visual>
    <collision>
      <origin
        xyz="0 0 0"
        rpy="0 0 0" />
      <geometry>
        <mesh
          filename="package://ask_3_description/meshes/LF_Link3.STL" />
      </geometry>
    </collision>
  </link>
  <joint
    name="LF_KFE"
    type="revolute">
    <origin
      xyz="-0.18062 0.17285 0.0947"
      rpy="0 0 0" />
    <parent
      link="LF_Link2" />
    <child
      link="LF_Link3" />
    <axis
      xyz="0 0 1" />
    <limit
      lower="-3.14"
      upper="3.14"
      effort="50"
      velocity="1000" />
  </joint>
  <link
    name="LH_Link1">
    <inertial>
      <origin
        xyz="0.015742 -2.0009E-06 -0.05652"
        rpy="0 0 0" />
      <mass
        value="0.84408" />
      <inertia
        ixx="0.0011915"
        ixy="2.989E-08"
        ixz="-1.8508E-06"
        iyy="0.00074578"
        iyz="5.548E-08"
        izz="0.00064082" />
    </inertial>
    <visual>
      <origin
        xyz="0 0 0"
        rpy="0 0 0" />
      <geometry>
        <mesh
          filename="package://ask_3_description/meshes/LH_Link1.STL" />
      </geometry>
      <material
        name="">
        <color
          rgba="0.89804 0.91765 0.92941 1" />
      </material>
    </visual>
    <collision>
      <origin
        xyz="0 0 0"
        rpy="0 0 0" />
      <geometry>
        <mesh
          filename="package://ask_3_description/meshes/LH_Link1.STL" />
      </geometry>
    </collision>
  </link>
  <joint
    name="LH_HAA"
    type="revolute">
    <origin
      xyz="-0.1965 0.072 0"
      rpy="-1.5708 0 -1.5708" />
    <parent
      link="base" />
    <child
      link="LH_Link1" />
    <axis
      xyz="0 0 1" />
    <limit
      lower="-3.14"
      upper="3.14"
      effort="50"
      velocity="1000" />
  </joint>
  <link
    name="LH_Link2">
    <inertial>
      <origin
        xyz="-0.016441 0.016704 0.067293"
        rpy="0 0 0" />
      <mass
        value="1.8166" />
      <inertia
        ixx="0.0032804"
        ixy="0.0017872"
        ixz="-2.1582E-06"
        iyy="0.0035757"
        iyz="1.8756E-06"
        izz="0.0065662" />
    </inertial>
    <visual>
      <origin
        xyz="0 0 0"
        rpy="0 0 0" />
      <geometry>
        <mesh
          filename="package://ask_3_description/meshes/LH_Link2.STL" />
      </geometry>
      <material
        name="">
        <color
          rgba="0.027451 0.40784 0.36471 1" />
      </material>
    </visual>
    <collision>
      <origin
        xyz="0 0 0"
        rpy="0 0 0" />
      <geometry>
        <mesh
          filename="package://ask_3_description/meshes/LH_Link2.STL" />
      </geometry>
    </collision>
  </link>
  <joint
    name="LH_HFE"
    type="revolute">
    <origin
      xyz="0.004 0 -0.066"
      rpy="0.0 -1.5708 0" />
    <parent
      link="LH_Link1" />
    <child
      link="LH_Link2" />
    <axis
      xyz="0 0 1" />
    <limit
      lower="-3.14"
      upper="3.14"
      effort="50"
      velocity="1000" />
  </joint>
  <link
    name="LH_Link3">
    <inertial>
      <origin
        xyz="0.070825 0.071358 -0.0025021"
        rpy="0 0 0" />
      <mass
        value="0.20609" />
      <inertia
        ixx="0.00068935"
        ixy="-0.00080672"
        ixz="1.2987E-08"
        iyy="0.001044"
        iyz="8.261E-09"
        izz="0.0017245" />
    </inertial>
    <visual>
      <origin
        xyz="0 0 0"
        rpy="0 0 0" />
      <geometry>
        <mesh
          filename="package://ask_3_description/meshes/LH_Link3.STL" />
      </geometry>
      <material
        name="">
        <color
          rgba="0.89804 0.91765 0.92941 1" />
      </material>
    </visual>
    <collision>
      <origin
        xyz="0 0 0"
        rpy="0 0 0" />
      <geometry>
        <mesh
          filename="package://ask_3_description/meshes/LH_Link3.STL" />
      </geometry>
    </collision>
  </link>
  <joint
    name="LH_KFE"
    type="revolute">
    <origin
      xyz="-0.18051 0.17297 0.0947"
      rpy="0 0 0" />
    <parent
      link="LH_Link2" />
    <child
      link="LH_Link3" />
    <axis
      xyz="0 0 1" />
    <limit
      lower="-3.14"
      upper="3.14"
      effort="50"
      velocity="1000" />
  </joint>
  <link
    name="RF_Link1">
    <inertial>
      <origin
        xyz="-0.015742 -2.0009E-06 0.05652"
        rpy="0 0 0" />
      <mass
        value="0.84408" />
      <inertia
        ixx="0.0011915"
        ixy="-2.989E-08"
        ixz="-1.8508E-06"
        iyy="0.00074578"
        iyz="-5.548E-08"
        izz="0.00064082" />
    </inertial>
    <visual>
      <origin
        xyz="0 0 0"
        rpy="0 0 0" />
      <geometry>
        <mesh
          filename="package://ask_3_description/meshes/RF_Link1.STL" />
      </geometry>
      <material
        name="">
        <color
          rgba="0.89804 0.91765 0.92941 1" />
      </material>
    </visual>
    <collision>
      <origin
        xyz="0 0 0"
        rpy="0 0 0" />
      <geometry>
        <mesh
          filename="package://ask_3_description/meshes/RF_Link1.STL" />
      </geometry>
    </collision>
  </link>
  <joint
    name="RF_HAA"
    type="revolute">
    <origin
      xyz="0.1965 -0.072 0"
      rpy="-1.5708 0 -1.5708" />
    <parent
      link="base" />
    <child
      link="RF_Link1" />
    <axis
      xyz="0 0 1" />
    <limit
      lower="-3.14"
      upper="3.14"
      effort="50"
      velocity="1000" />
  </joint>
  <link
    name="RF_Link2">
    <inertial>
      <origin
        xyz="-0.01645 0.016695 -0.067293"
        rpy="0 0 0" />
      <mass
        value="1.8166" />
      <inertia
        ixx="0.0032782"
        ixy="0.001787"
        ixz="2.082E-06"
        iyy="0.0035779"
        iyz="-1.9593E-06"
        izz="0.0065662" />
    </inertial>
    <visual>
      <origin
        xyz="0 0 0"
        rpy="0 0 0" />
      <geometry>
        <mesh
          filename="package://ask_3_description/meshes/RF_Link2.STL" />
      </geometry>
      <material
        name="">
        <color
          rgba="0.027451 0.40784 0.36471 1" />
      </material>
    </visual>
    <collision>
      <origin
        xyz="0 0 0"
        rpy="0 0 0" />
      <geometry>
        <mesh
          filename="package://ask_3_description/meshes/RF_Link2.STL" />
      </geometry>
    </collision>
  </link>
  <joint
    name="RF_HFE"
    type="revolute">
    <origin
      xyz="-0.004 0 0.066"
      rpy="0.0 -1.5708 0" />
    <parent
      link="RF_Link1" />
    <child
      link="RF_Link2" />
    <axis
      xyz="0 0 1" />
    <limit
      lower="-3.14"
      upper="3.14"
      effort="50"
      velocity="1000" />
  </joint>
  <link
    name="RF_Link3">
    <inertial>
      <origin
        xyz="0.070778 0.071405 -0.0025021"
        rpy="0 0 0" />
      <mass
        value="0.20609" />
      <inertia
        ixx="0.00069042"
        ixy="-0.00080696"
        ixz="1.2982E-08"
        iyy="0.001043"
        iyz="8.2699E-09"
        izz="0.0017245" />
    </inertial>
    <visual>
      <origin
        xyz="0 0 0"
        rpy="0 0 0" />
      <geometry>
        <mesh
          filename="package://ask_3_description/meshes/RF_Link3.STL" />
      </geometry>
      <material
        name="">
        <color
          rgba="0.89804 0.91765 0.92941 1" />
      </material>
    </visual>
    <collision>
      <origin
        xyz="0 0 0"
        rpy="0 0 0" />
      <geometry>
        <mesh
          filename="package://ask_3_description/meshes/RF_Link3.STL" />
      </geometry>
    </collision>
  </link>
  <joint
    name="RF_KFE"
    type="revolute">
    <origin
      xyz="-0.18062 0.17285 -0.0897"
      rpy="0 0 0" />
    <parent
      link="RF_Link2" />
    <child
      link="RF_Link3" />
    <axis
      xyz="0 0 1" />
    <limit
      lower="-3.14"
      upper="3.14"
      effort="50"
      velocity="1000" />
  </joint>
  <link
    name="RH_Link1">
    <inertial>
      <origin
        xyz="-0.015742 2.0009E-06 -0.05652"
        rpy="0 0 0" />
      <mass
        value="0.84408" />
      <inertia
        ixx="0.0011915"
        ixy="2.989E-08"
        ixz="1.8508E-06"
        iyy="0.00074578"
        iyz="-5.548E-08"
        izz="0.00064082" />
    </inertial>
    <visual>
      <origin
        xyz="0 0 0"
        rpy="0 0 0" />
      <geometry>
        <mesh
          filename="package://ask_3_description/meshes/RH_Link1.STL" />
      </geometry>
      <material
        name="">
        <color
          rgba="0.89804 0.91765 0.92941 1" />
      </material>
    </visual>
    <collision>
      <origin
        xyz="0 0 0"
        rpy="0 0 0" />
      <geometry>
        <mesh
          filename="package://ask_3_description/meshes/RH_Link1.STL" />
      </geometry>
    </collision>
  </link>
  <joint
    name="RH_HAA"
    type="revolute">
    <origin
      xyz="-0.1965 -0.072 0"
      rpy="-1.5708 0 -1.5708" />
    <parent
      link="base" />
    <child
      link="RH_Link1" />
    <axis
      xyz="0 0 1" />
    <limit
      lower="-3.14"
      upper="3.14"
      effort="50"
      velocity="1000" />
  </joint>
  <link
    name="RH_Link2">
    <inertial>
      <origin
        xyz="-0.016439 0.016706 -0.067293"
        rpy="0 0 0" />
      <mass
        value="1.8166" />
      <inertia
        ixx="0.0032805"
        ixy="0.0017872"
        ixz="2.0807E-06"
        iyy="0.0035756"
        iyz="-1.9607E-06"
        izz="0.0065662" />
    </inertial>
    <visual>
      <origin
        xyz="0 0 0"
        rpy="0 0 0" />
      <geometry>
        <mesh
          filename="package://ask_3_description/meshes/RH_Link2.STL" />
      </geometry>
      <material
        name="">
        <color
          rgba="0.027451 0.40784 0.36471 1" />
      </material>
    </visual>
    <collision>
      <origin
        xyz="0 0 0"
        rpy="0 0 0" />
      <geometry>
        <mesh
          filename="package://ask_3_description/meshes/RH_Link2.STL" />
      </geometry>
    </collision>
  </link>
  <joint
    name="RH_HFE"
    type="revolute">
    <origin
      xyz="-0.004 0 -0.066"
      rpy="0.0 -1.5708 0" />
    <parent
      link="RH_Link1" />
    <child
      link="RH_Link2" />
    <axis
      xyz="0 0 1" />
    <limit
      lower="-3.14"
      upper="3.14"
      effort="50"
      velocity="1000" />
  </joint>
  <link
    name="RH_Link3">
    <inertial>
      <origin
        xyz="0.070825 0.071358 -0.0025021"
        rpy="0 0 0" />
      <mass
        value="0.20609" />
      <inertia
        ixx="0.00068935"
        ixy="-0.00080672"
        ixz="1.2987E-08"
        iyy="0.001044"
        iyz="8.261E-09"
        izz="0.0017245" />
    </inertial>
    <visual>
      <origin
        xyz="0 0 0"
        rpy="0 0 0" />
      <geometry>
        <mesh
          filename="package://ask_3_description/meshes/RH_Link3.STL" />
      </geometry>
      <material
        name="">
        <color
          rgba="0.89804 0.91765 0.92941 1" />
      </material>
    </visual>
    <collision>
      <origin
        xyz="0 0 0"
        rpy="0 0 0" />
      <geometry>
        <mesh
          filename="package://ask_3_description/meshes/RH_Link3.STL" />
      </geometry>
    </collision>
  </link>
  <joint
    name="RH_KFE"
    type="revolute">
    <origin
      xyz="-0.18051 0.17297 -0.0897"
      rpy="0 0 0" />
    <parent
      link="RH_Link2" />
    <child
      link="RH_Link3" />
    <axis
      xyz="0 0 1" />
    <limit
      lower="-3.14"
      upper="3.14"
      effort="50"
      velocity="1000" />
  </joint>
  
  <link name="LF_foot">
    <visual>
     <origin xyz="0 0 0"/>
      <geometry>
        <sphere radius="0.02"/>
      </geometry>
    </visual>
    <collision>
      <origin rpy="0 0 0" xyz="0 0 0"/>
      <geometry>
        <sphere radius="0.02"/>
      </geometry>
    </collision>
  </link>
  <joint name="LF_ankle" type="fixed">
    <parent link="LF_Link3"/>
    <child link="LF_foot"/>
    <origin rpy="0 0 0" xyz="0.18 0.16 -0.002"/>
  </joint>
  
  <link name="LH_foot">
    <visual>
     <origin xyz="0 0 0"/>
      <geometry>
        <sphere radius="0.02"/>
      </geometry>
    </visual>
    <collision>
      <origin rpy="0 0 0" xyz="0 0 0"/>
      <geometry>
        <sphere radius="0.02"/>
      </geometry>
    </collision>
  </link>
  <joint name="LH_ankle" type="fixed">
    <parent link="LH_Link3"/>
    <child link="LH_foot"/>
    <origin rpy="0 0 0" xyz="0.18 0.16 -0.002"/>
  </joint>
  
  <link name="RF_foot">
    <visual>
     <origin xyz="0 0 0"/>
      <geometry>
        <sphere radius="0.02"/>
      </geometry>
    </visual>
    <collision>
      <origin rpy="0 0 0" xyz="0 0 0"/>
      <geometry>
        <sphere radius="0.02"/>
      </geometry>
    </collision>
  </link>
  <joint name="RF_ankle" type="fixed">
    <parent link="RF_Link3"/>
    <child link="RF_foot"/>
    <origin rpy="0 0 0" xyz="0.18 0.16 -0.002"/>
  </joint>
  
   <link name="RH_foot">
    <visual>
     <origin xyz="0 0 0"/>
      <geometry>
        <sphere radius="0.02"/>
      </geometry>
    </visual>
    <collision>
      <origin rpy="0 0 0" xyz="0 0 0"/>
      <geometry>
        <sphere radius="0.02"/>
      </geometry>
    </collision>
  </link>
  <joint name="RH_ankle" type="fixed">
    <parent link="RH_Link3"/>
    <child link="RH_foot"/>
    <origin rpy="0 0 0" xyz="0.18 0.16 -0.002"/>
  </joint>
  
  <!-- Gazebo customization -->
  <gazebo reference="RF_foot">
    <kp>1000000.0</kp>
    <kd>100.0</kd>
    <mu1>0.8</mu1>
    <mu2>0.8</mu2>
  </gazebo>
  
  <gazebo reference="LF_foot">
    <kp>1000000.0</kp>
    <kd>100.0</kd>
    <mu1>0.8</mu1>
    <mu2>0.8</mu2>
  </gazebo>
  
  <gazebo reference="RH_foot">
    <kp>1000000.0</kp>
    <kd>100.0</kd>
    <mu1>0.8</mu1>
    <mu2>0.8</mu2>
  </gazebo>

  <gazebo reference="LH_foot">
    <kp>1000000.0</kp>
    <kd>100.0</kd>
    <mu1>0.8</mu1>
    <mu2>0.8</mu2>
  </gazebo>
</robot>
